Workbook
Name Amp1_P: [1]DUT!$F:$F
Name Amp1_R1: [1]Ref1!$I:$I
Name Amp1_R2: [1]Ref2!$I:$I
Name Amp1_R3: [1]Ref3!$I:$I
Name Amp2_P: [1]DUT!$G:$G
Name Amp2_R1: [1]Ref1!$J:$J
Name Amp2_R2: [1]Ref2!$J:$J
Name Amp2_R3: [1]Ref3!$J:$J
Name c_A1: [1]Ref1!$K:$K
Name c_A2: [1]Ref2!$K:$K
Name c_A3: [1]Ref3!$K:$K
Name c_AP: [1]DUT!$H:$H
Name c_WL_cell: [1]DUT!$B:$B
Name c_WL_trap: [1]DUT!$C:$C
Name eps_R1: [1]Ref1!$B:$B
Name eps_R2: [1]Ref2!$B:$B
Name eps_R3: [1]Ref3!$B:$B
Name i_P: [1]Measure!$E:$E
Name i_P0: [1]Measure!$C:$C
Name i_R1: [1]Measure!$I:$I
Name i_R10: [1]Measure!$G:$G
Name i_R2: [1]Measure!$M:$M
Name i_R20: [1]Measure!$K:$K
Name i_R3: [1]Measure!$Q:$Q
Name i_R30: [1]Measure!$O:$O
Name N: [1]Eval!$J$1
Name nue_R1: [1]Ref1!$E:$E
Name nue_R2: [1]Ref2!$E:$E
Name nue_R3: [1]Ref3!$E:$E
Name u_c_A1: [1]Ref1!$L:$L
Name u_c_A2: [1]Ref2!$L:$L
Name u_c_A3: [1]Ref3!$L:$L
Name u_c_AP: [1]DUT!$I:$I
Name u_epsr_R1: [1]Ref1!$F:$F
Name u_epsr_R2: [1]Ref2!$F:$F
Name u_epsr_R3: [1]Ref3!$F:$F
Name u_I_P: [1]Measure!$D:$D
Name u_I_P0: [1]Measure!$B:$B
Name u_i_R1: [1]Measure!$H:$H
Name u_i_R10: [1]Measure!$F:$F
Name u_i_R2: [1]Measure!$L:$L
Name u_i_R20: [1]Measure!$J:$J
Name u_i_R3: [1]Measure!$P:$P
Name u_i_R30: [1]Measure!$N:$N
Name WL_Ref1: [1]Ref1!$A:$A

Sheet 73321 23 PTB
A1: λ / nm | B1: s(λ) / (A/W) | C1: U(s(λ)) / (A/W) | D1: ɸ(λ) / (µW) | G1: interpolation | H1: s(λ) / (A/W) | I1: U(s(λ)) / (A/W) | J1: U(s(λ)) / (%) | L1: interpolation | M1: s(λ) / (A/W) | N1: U(s(λ)) / (A/W) | O1: U(s(λ)) / (%)
A2: 250 | B2: 0.21471 | C2: 0.00082 | D2: 0.28 | G2: 250 | H2: =_xll.Interpolate($A$2:$A$118,B$2:B$118,$G2) -> 0.21471 | I2: =_xll.Interpolate($A$2:$A$118,$C$2:$C$118,$G2) -> 0.00082 | J2: =I2/H2*100 -> 0.38191048 | L2: 250 | M2: =_xll.Interpolate($A$2:$A$118,B$2:B$118,$L2) -> 0.21471 | N2: =_xll.Interpolate($A$2:$A$118,$C$2:$C$118,$L2) -> 0.00082 | O2: =N2/M2*100 -> 0.38191048
A3: 255 | B3: 0.21292 | C3: 0.00077 | D3: 0.3 | G3: 260 | H3: =_xll.Interpolate($A$2:$A$118,B$2:B$118,$G3) -> 0.21074 | I3: =_xll.Interpolate($A$2:$A$118,$C$2:$C$118,$G3) -> 0.00073 | J3: =I3/H3*100 -> 0.34639841 | L3: 255 | M3: =_xll.Interpolate($A$2:$A$118,B$2:B$118,$L3) -> 0.21292 | N3: =_xll.Interpolate($A$2:$A$118,$C$2:$C$118,$L3) -> 0.00077 | O3: =N3/M3*100 -> 0.36163817
A4: 260 | B4: 0.21074 | C4: 0.00073 | D4: 0.31 | G4: 270 | H4: =_xll.Interpolate($A$2:$A$118,B$2:B$118,$G4) -> 0.20607 | I4: =_xll.Interpolate($A$2:$A$118,$C$2:$C$118,$G4) -> 0.00064 | J4: =I4/H4*100 -> 0.31057408 | L4: 260 | M4: =_xll.Interpolate($A$2:$A$118,B$2:B$118,$L4) -> 0.21074 | N4: =_xll.Interpolate($A$2:$A$118,$C$2:$C$118,$L4) -> 0.00073 | O4: =N4/M4*100 -> 0.34639841
A5: 265 | B5: 0.20817 | C5: 0.00068 | D5: 0.32 | G5: 280 | H5: =_xll.Interpolate($A$2:$A$118,B$2:B$118,$G5) -> 0.21261 | I5: =_xll.Interpolate($A$2:$A$118,$C$2:$C$118,$G5) -> 0.00061 | J5: =I5/H5*100 -> 0.28691031 | L5: 265 | M5: =_xll.Interpolate($A$2:$A$118,B$2:B$118,$L5) -> 0.20817 | N5: =_xll.Interpolate($A$2:$A$118,$C$2:$C$118,$L5) -> 0.00068 | O5: =N5/M5*100 -> 0.3266561
A6: 270 | B6: 0.20607 | C6: 0.00064 | D6: 0.23 | G6: 290 | H6: =_xll.Interpolate($A$2:$A$118,B$2:B$118,$G6) -> 0.22727 | I6: =_xll.Interpolate($A$2:$A$118,$C$2:$C$118,$G6) -> 0.00061 | J6: =I6/H6*100 -> 0.26840322 | L6: 270 | M6: =_xll.Interpolate($A$2:$A$118,B$2:B$118,$L6) -> 0.20607 | N6: =_xll.Interpolate($A$2:$A$118,$C$2:$C$118,$L6) -> 0.00064 | O6: =N6/M6*100 -> 0.31057408
A7: 275 | B7: 0.20708 | C7: 0.0006 | D7: 0.16 | G7: 300 | H7: =_xll.Interpolate($A$2:$A$118,B$2:B$118,$G7) -> 0.23396 | I7: =_xll.Interpolate($A$2:$A$118,$C$2:$C$118,$G7) -> 0.00056 | J7: =I7/H7*100 -> 0.23935716 | L7: 275 | M7: =_xll.Interpolate($A$2:$A$118,B$2:B$118,$L7) -> 0.20708 | N7: =_xll.Interpolate($A$2:$A$118,$C$2:$C$118,$L7) -> 0.0006 | O7: =N7/M7*100 -> 0.28974309
A8: 280 | B8: 0.21261 | C8: 0.00061 | D8: 0.2 | G8: 310 | H8: =_xll.Interpolate($A$2:$A$118,B$2:B$118,$G8) -> 0.23809 | I8: =_xll.Interpolate($A$2:$A$118,$C$2:$C$118,$G8) -> 0.00064 | J8: =I8/H8*100 -> 0.26880591 | L8: 280 | M8: =_xll.Interpolate($A$2:$A$118,B$2:B$118,$L8) -> 0.21261 | N8: =_xll.Interpolate($A$2:$A$118,$C$2:$C$118,$L8) -> 0.00061 | O8: =N8/M8*100 -> 0.28691031
A9: 285 | B9: 0.22057 | C9: 0.00059 | D9: 0.23 | G9: 320 | H9: =_xll.Interpolate($A$2:$A$118,B$2:B$118,$G9) -> 0.2428 | I9: =_xll.Interpolate($A$2:$A$118,$C$2:$C$118,$G9) -> 0.00073 | J9: =I9/H9*100 -> 0.30065898 | L9: 285 | M9: =_xll.Interpolate($A$2:$A$118,B$2:B$118,$L9) -> 0.22057 | N9: =_xll.Interpolate($A$2:$A$118,$C$2:$C$118,$L9) -> 0.00059 | O9: =N9/M9*100 -> 0.26748878
A10: 290 | B10: 0.22727 | C10: 0.00061 | D10: 0.27 | G10: 330 | H10: =_xll.Interpolate($A$2:$A$118,B$2:B$118,$G10) -> 0.24863 | I10: =_xll.Interpolate($A$2:$A$118,$C$2:$C$118,$G10) -> 0.00059 | J10: =I10/H10*100 -> 0.23730041 | L10: 290 | M10: =_xll.Interpolate($A$2:$A$118,B$2:B$118,$L10) -> 0.22727 | N10: =_xll.Interpolate($A$2:$A$118,$C$2:$C$118,$L10) -> 0.00061 | O10: =N10/M10*100 -> 0.26840322
A11: 295 | B11: 0.2314 | C11: 0.0006 | D11: 0.3 | G11: 340 | H11: =_xll.Interpolate($A$2:$A$118,B$2:B$118,$G11) -> 0.25526 | I11: =_xll.Interpolate($A$2:$A$118,$C$2:$C$118,$G11) -> 0.00061 | J11: =I11/H11*100 -> 0.23897203 | L11: 295 | M11: =_xll.Interpolate($A$2:$A$118,B$2:B$118,$L11) -> 0.2314 | N11: =_xll.Interpolate($A$2:$A$118,$C$2:$C$118,$L11) -> 0.0006 | O11: =N11/M11*100 -> 0.25929127
A12: 300 | B12: 0.23396 | C12: 0.00056 | D12: 0.34 | G12: 350 | H12: =_xll.Interpolate($A$2:$A$118,B$2:B$118,$G12) -> 0.26157 | I12: =_xll.Interpolate($A$2:$A$118,$C$2:$C$118,$G12) -> 0.00063 | J12: =I12/H12*100 -> 0.24085331 | L12: 300 | M12: =_xll.Interpolate($A$2:$A$118,B$2:B$118,$L12) -> 0.23396 | N12: =_xll.Interpolate($A$2:$A$118,$C$2:$C$118,$L12) -> 0.00056 | O12: =N12/M12*100 -> 0.23935716
A13: 305 | B13: 0.23601 | C13: 0.00058 | D13: 0.37 | G13: 360 | H13: =_xll.Interpolate($A$2:$A$118,B$2:B$118,$G13) -> 0.26688 | I13: =_xll.Interpolate($A$2:$A$118,$C$2:$C$118,$G13) -> 0.00062 | J13: =I13/H13*100 -> 0.23231415 | L13: 305 | M13: =_xll.Interpolate($A$2:$A$118,B$2:B$118,$L13) -> 0.23601 | N13: =_xll.Interpolate($A$2:$A$118,$C$2:$C$118,$L13) -> 0.00058 | O13: =N13/M13*100 -> 0.2457523
... A87: 940 | B87: 0.75043 | C87: 0.00066 | D87: 2.8 | G87: 1100 | H87: =_xll.Interpolate($A$2:$A$118,B$2:B$118,$G87) -> 0.0904 | I87: =_xll.Interpolate($A$2:$A$118,$C$2:$C$118,$G87) -> 0.0011 | J87: =I87/H87*100 -> 1.2168142 | L87: 675 | M87: =_xll.Interpolate($A$2:$A$118,B$2:B$118,$L87) -> 0.54152375 | N87: =_xll.Interpolate($A$2:$A$118,$C$2:$C$118,$L87) -> 0.000365 | O87: =N87/M87*100 -> 0.067402399
A88: 950 | B88: 0.75386 | C88: 0.00081 | D88: 3 | L88: 680 | M88: =_xll.Interpolate($A$2:$A$118,B$2:B$118,$L88) -> 0.54558 | N88: =_xll.Interpolate($A$2:$A$118,$C$2:$C$118,$L88) -> 0.00037 | O88: =N88/M88*100 -> 0.067817735
A89: 955 | B89: 0.75437 | C89: 0.00088 | D89: 3.2 | L89: 685 | M89: =_xll.Interpolate($A$2:$A$118,B$2:B$118,$L89) -> 0.54963 | N89: =_xll.Interpolate($A$2:$A$118,$C$2:$C$118,$L89) -> 0.00037 | O89: =N89/M89*100 -> 0.067318014
A90: 960 | B90: 0.75375 | C90: 0.00089 | D90: 3.3 | L90: 690 | M90: =_xll.Interpolate($A$2:$A$118,B$2:B$118,$L90) -> 0.55368 | N90: =_xll.Interpolate($A$2:$A$118,$C$2:$C$118,$L90) -> 0.00037 | O90: =N90/M90*100 -> 0.066825603
A91: 965 | B91: 0.75175 | C91: 0.00088 | D91: 3.4 | L91: 695 | M91: =_xll.Interpolate($A$2:$A$118,B$2:B$118,$L91) -> 0.55774 | N91: =_xll.Interpolate($A$2:$A$118,$C$2:$C$118,$L91) -> 0.000375 | O91: =N91/M91*100 -> 0.06723563
A92: 970 | B92: 0.74807 | C92: 0.00091 | D92: 3.5 | L92: 700 | M92: =_xll.Interpolate($A$2:$A$118,B$2:B$118,$L92) -> 0.5618 | N92: =_xll.Interpolate($A$2:$A$118,$C$2:$C$118,$L92) -> 0.00038 | O92: =N92/M92*100 -> 0.067639729
A93: 975 | B93: 0.7424 | C93: 0.001 | D93: 3.6 | L93: 705 | M93: =_xll.Interpolate($A$2:$A$118,B$2:B$118,$L93) -> 0.56585125 | N93: =_xll.Interpolate($A$2:$A$118,$C$2:$C$118,$L93) -> 0.00038 | O93: =N93/M93*100 -> 0.067155458
A94: 980 | B94: 0.7347 | C94: 0.0011 | D94: 3.7 | L94: 710 | M94: =_xll.Interpolate($A$2:$A$118,B$2:B$118,$L94) -> 0.5699 | N94: =_xll.Interpolate($A$2:$A$118,$C$2:$C$118,$L94) -> 0.00038 | O94: =N94/M94*100 -> 0.066678365
A95: 985 | B95: 0.7244 | C95: 0.0013 | D95: 3.8 | L95: 715 | M95: =_xll.Interpolate($A$2:$A$118,B$2:B$118,$L95) -> 0.57395062 | N95: =_xll.Interpolate($A$2:$A$118,$C$2:$C$118,$L95) -> 0.000385 | O95: =N95/M95*100 -> 0.067078941
A96: 990 | B96: 0.7116 | C96: 0.0015 | D96: 3.9 | L96: 720 | M96: =_xll.Interpolate($A$2:$A$118,B$2:B$118,$L96) -> 0.578 | N96: =_xll.Interpolate($A$2:$A$118,$C$2:$C$118,$L96) -> 0.00039 | O96: =N96/M96*100 -> 0.067474048
A97: 995 | B97: 0.6957 | C97: 0.0016 | D97: 3.9 | L97: 725 | M97: =_xll.Interpolate($A$2:$A$118,B$2:B$118,$L97) -> 0.582045 | N97: =_xll.Interpolate($A$2:$A$118,$C$2:$C$118,$L97) -> 0.00039 | O97: =N97/M97*100 -> 0.067005128
A98: 1000 | B98: 0.6766 | C98: 0.0017 | D98: 4 | L98: 730 | M98: =_xll.Interpolate($A$2:$A$118,B$2:B$118,$L98) -> 0.58609 | N98: =_xll.Interpolate($A$2:$A$118,$C$2:$C$118,$L98) -> 0.00039 | O98: =N98/M98*100 -> 0.066542681
A99: 1005 | B99: 0.6548 | C99: 0.0042 | D99: 4.1 | L99: 735 | M99: =_xll.Interpolate($A$2:$A$118,B$2:B$118,$L99) -> 0.59014125 | N99: =_xll.Interpolate($A$2:$A$118,$C$2:$C$118,$L99) -> 0.000395 | O99: =N99/M99*100 -> 0.066933128
... A118: 1100 | B118: 0.0904 | C118: 0.0011 | D118: 4.4 | L118: 830 | M118: =_xll.Interpolate($A$2:$A$118,B$2:B$118,$L118) -> 0.66674 | N118: =_xll.Interpolate($A$2:$A$118,$C$2:$C$118,$L118) -> 0.00045 | O118: =N118/M118*100 -> 0.067492576
L119: 835 | M119: =_xll.Interpolate($A$2:$A$118,B$2:B$118,$L119) -> 0.67075563 | N119: =_xll.Interpolate($A$2:$A$118,$C$2:$C$118,$L119) -> 0.000455 | O119: =N119/M119*100 -> 0.067833945
L120: 840 | M120: =_xll.Interpolate($A$2:$A$118,B$2:B$118,$L120) -> 0.67477 | N120: =_xll.Interpolate($A$2:$A$118,$C$2:$C$118,$L120) -> 0.00046 | O120: =N120/M120*100 -> 0.068171377
L121: 845 | M121: =_xll.Interpolate($A$2:$A$118,B$2:B$118,$L121) -> 0.67879 | N121: =_xll.Interpolate($A$2:$A$118,$C$2:$C$118,$L121) -> 0.00046 | O121: =N121/M121*100 -> 0.067767645
L122: 850 | M122: =_xll.Interpolate($A$2:$A$118,B$2:B$118,$L122) -> 0.68281 | N122: =_xll.Interpolate($A$2:$A$118,$C$2:$C$118,$L122) -> 0.00046 | O122: =N122/M122*100 -> 0.067368668
L123: 855 | M123: =_xll.Interpolate($A$2:$A$118,B$2:B$118,$L123) -> 0.68682562 | N123: =_xll.Interpolate($A$2:$A$118,$C$2:$C$118,$L123) -> 0.000464375 | O123: =N123/M123*100 -> 0.067611776
L124: 860 | M124: =_xll.Interpolate($A$2:$A$118,B$2:B$118,$L124) -> 0.69084 | N124: =_xll.Interpolate($A$2:$A$118,$C$2:$C$118,$L124) -> 0.00047 | O124: =N124/M124*100 -> 0.068033119
L125: 865 | M125: =_xll.Interpolate($A$2:$A$118,B$2:B$118,$L125) -> 0.694855 | N125: =_xll.Interpolate($A$2:$A$118,$C$2:$C$118,$L125) -> 0.000475 | O125: =N125/M125*100 -> 0.068359586
L126: 870 | M126: =_xll.Interpolate($A$2:$A$118,B$2:B$118,$L126) -> 0.69887 | N126: =_xll.Interpolate($A$2:$A$118,$C$2:$C$118,$L126) -> 0.00048 | O126: =N126/M126*100 -> 0.068682301
L127: 875 | M127: =_xll.Interpolate($A$2:$A$118,B$2:B$118,$L127) -> 0.70288562 | N127: =_xll.Interpolate($A$2:$A$118,$C$2:$C$118,$L127) -> 0.000484375 | O127: =N127/M127*100 -> 0.06891235
L128: 880 | M128: =_xll.Interpolate($A$2:$A$118,B$2:B$118,$L128) -> 0.7069 | N128: =_xll.Interpolate($A$2:$A$118,$C$2:$C$118,$L128) -> 0.00049 | O128: =N128/M128*100 -> 0.069316735
L129: 885 | M129: =_xll.Interpolate($A$2:$A$118,B$2:B$118,$L129) -> 0.7109125 | N129: =_xll.Interpolate($A$2:$A$118,$C$2:$C$118,$L129) -> 0.00049875 | O129: =N129/M129*100 -> 0.070156313
L130: 890 | M130: =_xll.Interpolate($A$2:$A$118,B$2:B$118,$L130) -> 0.71492 | N130: =_xll.Interpolate($A$2:$A$118,$C$2:$C$118,$L130) -> 0.00051 | O130: =N130/M130*100 -> 0.071336653
... L172: 1100 | M172: =_xll.Interpolate($A$2:$A$118,B$2:B$118,$L172) -> 0.0904 | N172: =_xll.Interpolate($A$2:$A$118,$C$2:$C$118,$L172) -> 0.0011 | O172: =N172/M172*100 -> 1.2168142

Sheet Chk1
C1: comparison | M1: ideal QED:
C2: with "ideal QED" | M2: e | N2: 1.6021765e-19 | O2: C
M3: h | N3: 6.6260693e-34 | O3: J s
A4: WL / nm | M4: c | N4: 299792458 | O4: m / s
A5: 240 | B5: =A5*$N$7 -> 0.19357307
A6: ='73321 23 PTB'!G2 -> 250 | B6: =A6*$N$7 -> 0.20163861 | C6: ='73321 23 PTB'!H2/B6-1 -> 0.064825822 | M6: eps | N6: 806554.44 | O6: A/W /m
A7: ='73321 23 PTB'!G3 -> 260 | B7: =A7*$N$7 -> 0.20970416 | C7: ='73321 23 PTB'!H3/B7-1 -> 0.0049395508 | N7: 0.00080655444 | O7: A/W /nm
A8: ='73321 23 PTB'!G4 -> 270 | B8: =A8*$N$7 -> 0.2177697 | C8: ='73321 23 PTB'!H4/B8-1 -> -0.053725105 | N8: 0.80655444 | O8: A/W /microm
A9: ='73321 23 PTB'!G5 -> 280 | B9: =A9*$N$7 -> 0.22583524 | C9: ='73321 23 PTB'!H5/B9-1 -> -0.058561473 | N9: 1.2398419 | O9: microm / (A/W)
A10: ='73321 23 PTB'!G6 -> 290 | B10: =A10*$N$7 -> 0.23390079 | C10: ='73321 23 PTB'!H6/B10-1 -> -0.028348724 | N10: 0.000811601
A11: ='73321 23 PTB'!G7 -> 300 | B11: =A11*$N$7 -> 0.24196633 | C11: ='73321 23 PTB'!H7/B11-1 -> -0.033088626
A12: ='73321 23 PTB'!G8 -> 310 | B12: =A12*$N$7 -> 0.25003188 | C12: ='73321 23 PTB'!H8/B12-1 -> -0.047761421
A13: ='73321 23 PTB'!G9 -> 320 | B13: =A13*$N$7 -> 0.25809742 | C13: ='73321 23 PTB'!H9/B13-1 -> -0.059269954
A14: ='73321 23 PTB'!G10 -> 330 | B14: =A14*$N$7 -> 0.26616297 | C14: ='73321 23 PTB'!H10/B14-1 -> -0.065873051
A15: ='73321 23 PTB'!G11 -> 340 | B15: =A15*$N$7 -> 0.27422851 | C15: ='73321 23 PTB'!H11/B15-1 -> -0.069170456
A16: ='73321 23 PTB'!G12 -> 350 | B16: =A16*$N$7 -> 0.28229406 | C16: ='73321 23 PTB'!H12/B16-1 -> -0.073413008
A17: ='73321 23 PTB'!G13 -> 360 | B17: =A17*$N$7 -> 0.2903596 | C17: ='73321 23 PTB'!H13/B17-1 -> -0.080863867
A18: ='73321 23 PTB'!G14 -> 370 | B18: =A18*$N$7 -> 0.29842514 | C18: ='73321 23 PTB'!H14/B18-1 -> -0.083957887
A19: ='73321 23 PTB'!G15 -> 380 | B19: =A19*$N$7 -> 0.30649069 | C19: ='73321 23 PTB'!H15/B19-1 -> -0.073348685
A20: ='73321 23 PTB'!G16 -> 390 | B20: =A20*$N$7 -> 0.31455623 | C20: ='73321 23 PTB'!H16/B20-1 -> -0.060295208
A21: ='73321 23 PTB'!G17 -> 400 | B21: =A21*$N$7 -> 0.32262178 | C21: ='73321 23 PTB'!H17/B21-1 -> -0.050839029
A22: ='73321 23 PTB'!G18 -> 410 | B22: =A22*$N$7 -> 0.33068732 | C22: ='73321 23 PTB'!H18/B22-1 -> -0.042176768
... A25: ='73321 23 PTB'!G21 -> 440 | B25: =A25*$N$7 -> 0.35488396 | C25: ='73321 23 PTB'!H21/B25-1 -> -0.02773852
A26: ='73321 23 PTB'!G22 -> 450 | B26: =A26*$N$7 -> 0.3629495 | C26: ='73321 23 PTB'!H22/B26-1 -> -0.024630149 | D26: -0.01 | E26: 0
A27: ='73321 23 PTB'!G23 -> 460 | B27: =A27*$N$7 -> 0.37101504 | C27: ='73321 23 PTB'!H23/B27-1 -> -0.021872549 | D27: -0.009 | E27: 0
A28: ='73321 23 PTB'!G24 -> 470 | B28: =A28*$N$7 -> 0.37908059 | C28: ='73321 23 PTB'!H24/B28-1 -> -0.019496089 | D28: -0.008 | E28: 0
A29: ='73321 23 PTB'!G25 -> 480 | B29: =A29*$N$7 -> 0.38714613 | C29: ='73321 23 PTB'!H25/B29-1 -> -0.0173478 | D29: -0.007 | E29: 0
A30: ='73321 23 PTB'!G26 -> 490 | B30: =A30*$N$7 -> 0.39521168 | C30: ='73321 23 PTB'!H26/B30-1 -> -0.01559083 | D30: -0.006 | E30: 0
A31: ='73321 23 PTB'!G27 -> 500 | B31: =A31*$N$7 -> 0.40327722 | C31: ='73321 23 PTB'!H27/B31-1 -> -0.014003326 | D31: -0.005 | E31: 0
A32: ='73321 23 PTB'!G28 -> 510 | B32: =A32*$N$7 -> 0.41134277 | C32: ='73321 23 PTB'!H28/B32-1 -> -0.012672562 | D32: -0.005 | E32: 0
A33: ='73321 23 PTB'!G29 -> 520 | B33: =A33*$N$7 -> 0.41940831 | C33: ='73321 23 PTB'!H29/B33-1 -> -0.011583727 | D33: -0.005 | E33: 0
A34: ='73321 23 PTB'!G30 -> 530 | B34: =A34*$N$7 -> 0.42747386 | C34: ='73321 23 PTB'!H30/B34-1 -> -0.010629552 | D34: -0.005 | E34: 0
A35: ='73321 23 PTB'!G31 -> 540 | B35: =A35*$N$7 -> 0.4355394 | C35: ='73321 23 PTB'!H31/B35-1 -> -0.0098714381 | D35: -0.005 | E35: 0
A36: ='73321 23 PTB'!G32 -> 550 | B36: =A36*$N$7 -> 0.44360494 | C36: ='73321 23 PTB'!H32/B36-1 -> -0.0092310618 | D36: -0.005 | E36: 0
A37: ='73321 23 PTB'!G33 -> 560 | B37: =A37*$N$7 -> 0.45167049 | C37: ='73321 23 PTB'!H33/B37-1 -> -0.0087021163 | D37: -0.005 | E37: 0
... A71: ='73321 23 PTB'!G67 -> 900 | B71: =A71*$N$7 -> 0.725899 | C71: ='73321 23 PTB'!H67/B71-1 -> -0.0041176532 | D71: -0.01 | E71: 0
A72: ='73321 23 PTB'!G68 -> 910 | B72: =A72*$N$7 -> 0.73396454 | C72: ='73321 23 PTB'!H68/B72-1 -> -0.0043252019
A73: ='73321 23 PTB'!G69 -> 920 | B73: =A73*$N$7 -> 0.74203009 | C73: ='73321 23 PTB'!H69/B73-1 -> -0.0050673003
A74: ='73321 23 PTB'!G70 -> 930 | B74: =A74*$N$7 -> 0.75009563 | C74: ='73321 23 PTB'!H70/B74-1 -> -0.0068333069
A75: ='73321 23 PTB'!G71 -> 940 | B75: =A75*$N$7 -> 0.75816118 | C75: ='73321 23 PTB'!H71/B75-1 -> -0.010197275
...
